Workbook

Sheet Main
A1: General info | B1: General info | C1: General info | D1: General info | E1: General info | F1: General info | G1: General info | H1: General info | I1: General info | J1: General info | K1: General info | L1: General info | M1: General info | N1: General info | O1: General info | P1: General info | Q1: General info | R1: General info | S1: General info | T1: General info | U1: From report | V1: From report | W1: From report | X1: From report | Y1: From report | Z1: From report | AA1: From report | AB1: From report | AC1: From report | AD1: From report | AE1: From report | AF1: From report | AG1: From report | AH1: From report | AI1: From report | AJ1: From report | AK1: From report | AL1: From report | AM1: From report | AN1: From report | AO1: From report | AP1: From report | AQ1: From report | AR1: From report | AS1: From report | AT1: From report | AU1: From report | AV1: From report | AW1: From report | AX1: From report | AY1: From report | AZ1: From report | BA1: From report | BB1: From report | BC1: From report | BD1: Tracker info | BE1: Tracker info | BF1: Tracker info | BG1: Tracker info | BH1: Tracker info | BI1: Tracker info | BJ1: Tracker info | BK1: Additional info | BL1: Additional info | BM1: Additional info | BN1: Additional info | BO1: Additional info | BQ1: Additional info | BS1: Additional info | BW1: Additional info | BY1: Additional info | BZ1: Additional info | CA1: Additional info | CB1: Additional info | CF1: Additional info
K2: derived fromCC | L2: derived fromCC | M2: derived fromCC | N2: derived fromCC | O2: derived fromCC | P2: derived fromCC | Q2: derived fromCC | R2: derived fromCC | S2: derived fromCC | BO2: Equipment Usage Status | BQ2: Loading capacity / Грузоподьемность | BS2: Generator specifications | BW2: Compressor specifications | CB2: Target utlization
A3: Equipment | B3: Operation Status | C3: License | D3: Description | E3: Service Zone | F3: Class | G3: Location | H3: Serial Number | I3: VIN/Chassis No | J3: CC code | K3: CC status | L3: Division code | M3: CC name | N3: Division name | O3: Group code | P3: Group name | Q3: Department code | R3: Department name from WP | S3: Department name | T3: User Department (from Report) | U3: Title | V3: Fleet | W3: Allocation | X3: Writeoff Status | Y3: Fleet Active Date | Z3: Criticality | AA3: Manufacturer | AB3: Model | AC3: Currency | AD3: Capital Cost | AE3: Year | AF3: Age of Fleet (Yrs) | AG3: Body No | AH3: Engine No | AI3: Date of Registr. In GAI | AJ3: Technical Passport No | AK3: Date Acquired by user | AL3: Life Cycle 2 (years) | AM3: Commission Date | AN3: Withdrawal date | AO3: Total Counter Reading | AP3: Last Reading | AQ3: Last Reading Motor Hour | AR3: FrontTireSize | AS3: RearTireSize | AT3: FleetCode | AU3: PO | AV3: Replace in Year | AW3: TCO Requested Replace in Year | AX3: Replaced by | AY3: TCO Charge | AZ3: ID | BA3: Eng Model | BB3: Transmission model | BC3: NOTES | BD3: Tracker existence | BE3: WIALON Qty | BF3: WIALON "group" | BG3: IVMS Qty | BH3: IVMS "Registration number" | BI3: Vega Qty | BJ3: Vega "deviceId" | BK3: Assigned location | BL3: HDV/HDE classification | BM3: Expected metrics from trackers | BN3: Category | BO3: Equipment Usage Status | BP3: Justification if "Assigned" | BQ3: Weight-based, kg | BR3: Volume-based, m³ | BS3: System Voltage, V | BT3: Battery Capacity, Ah | BU3: Current, A | BV3: Alternator Output, kvA | BW3: Pneumatic Pressure, ft³ (CFM) | BX3: Work output, m³/h | BY3: Maintenance BP | BZ3: Contact number | CA3: Contact e-mail | CB3: if required | CC3: km/day | CD3: mh/day | CE3: comments | CF3: General comments | CG3: Assignee
A4: 108019 | B4: Active | C4: H725152 | D4: TRUCK HD RAILROAD INTERNATIONAL 7400 SBA | E4: TMF1 | F4: HDV Heavy Duty Vehicle | G4: Tengiz | H4: 1HTWEAAN9BJ374649 | I4: 1HTWEAAN9BJ374649 | J4: 20053 | K4: =IFERROR(VLOOKUP(J4,'CC directory'!A:B,2,),"") -> ACTIVE | L4: =IFERROR(VLOOKUP(J4,'CC directory'!A:D,4,),"") -> 200 | M4: =VLOOKUP(J4,'CC directory'!A:I,9,) -> RailRoad Maintenance | N4: =IFERROR(VLOOKUP(J4,'CC directory'!A:C,3,),"") -> Operations | O4: =IFERROR(VLOOKUP(J4,'CC directory'!A:F,6,),"") -> 207 | P4: =IFERROR(VLOOKUP(J4,'CC directory'!A:E,5,),"") -> Production Operations | Q4: =IFERROR(VLOOKUP(J4,'CC directory'!A:H,8,),"") -> 708 | R4: =IFERROR(VLOOKUP(J4,'CC directory'!A:G,7,),"") -> FIELD & EXPORT | S4: FIELD & EXPORT | T4: Rail Road Maintenance | U4: 518 | V4: Tengiz fleet | Z4: Critical | AA4: INTERNATIONAL | AB4: 7400 SBA 4X4 | AC4: USD | AD4: 282616.82 | AE4: 2010 | AF4: 12 | AH4: 2N8006413 | AJ4: ED00011925 | AK4: 40739 | AL4: 15 | AM4: 40758 | AO4: 162086 | AP4: 162086 | AR4: 295/75R22.5 | AS4: 445/50R22.5 | AT4: TRKINTHR 001 | AU4: 142005 | AV4: 2023 | AW4: 2026 | AY4: YES | AZ4: 519 | BA4: IN-LINE 6 | BB4: FR-9210B 10-SPD | BD4: =IF((BE4+BG4+BI4)>0, "YES", "NO") -> YES | BE4: 1 | BF4: INTERNATIONAL H725152 (ТШО 108019) | BG4: 1 | BH4: H 725152 | BI4: 0 | BK4: IB | BL4: Self-propelled motorized (HDV/HDE) - Wheeled | BM4: =VLOOKUP(BL4,'directory all'!C:D,2,) -> Mileage, engine hours, GPS | BN4: Recovery/service truck | BO4: Assigned | BQ4: N/A | BR4: N/A | BS4: N/A | BT4: N/A | BU4: N/A | BV4: N/A | BW4: N/A | BX4: N/A | BY4: TCO SCM Logistics | BZ4: 200-4683 | CA4: RRMLC@tengizchevroil.com | CB4: YES | CC4: 42.294 | CD4: 7.236 | CG4: Maintenance RailRoad
A5: 108020 | B5: Active | C5: H725510 | D5: TRUCK HD RECOVERY KENWORTH T800 | E5: TMF1 | F5: HDV Heavy Duty Vehicle | G5: Tengiz | H5: 1NKDL40X0CR302786 | I5: 1NKDL40X0CR302786 | J5: 13780 | K5: =IFERROR(VLOOKUP(J5,'CC directory'!A:B,2,),"") -> ACTIVE | L5: =IFERROR(VLOOKUP(J5,'CC directory'!A:D,4,),"") -> 200 | M5: =VLOOKUP(J5,'CC directory'!A:I,9,) -> Heavy Equipment Operations | N5: =IFERROR(VLOOKUP(J5,'CC directory'!A:C,3,),"") -> Operations | O5: =IFERROR(VLOOKUP(J5,'CC directory'!A:F,6,),"") -> 209 | P5: =IFERROR(VLOOKUP(J5,'CC directory'!A:E,5,),"") -> Supply Chain Management | Q5: =IFERROR(VLOOKUP(J5,'CC directory'!A:H,8,),"") -> 322 | R5: =IFERROR(VLOOKUP(J5,'CC directory'!A:G,7,),"") -> Tengiz Ground Transportation | S5: SCM Logistics | T5: Heavy Equipment Operations | U5: 519 | V5: Tengiz fleet | Z5: Critical | AA5: KENWORTH | AB5: T800 | AC5: USD | AD5: 281700 | AE5: 2011 | AF5: 12 | AH5: 79465100 | AJ5: ED00012108 | AK5: 40775 | AL5: 15 | AM5: 40779 | AO5: 119321 | AP5: 62200 | AR5: 445 / 65 R 22.5 | AS5: 11R24.5 | AT5: TRKKEN 003 | AU5: 150933 | AV5: 2021 | AW5: 2026 | AZ5: 520 | BA5: IN-LINE 6 | BB5: FRO15210C | BD5: =IF((BE5+BG5+BI5)>0, "YES", "NO") -> YES | BE5: 1 | BF5: KENWORTH H 725510 (ТШО 108020) | BG5: 1 | BH5: H 725510 | BI5: 0 | BK5: Industrial Base | BL5: Self-propelled motorized (HDV/HDE) - Wheeled | BM5: =VLOOKUP(BL5,'directory all'!C:D,2,) -> Mileage, engine hours, GPS | BN5: Recovery/service truck | BO5: Shared without conditions | BQ5: 10600 | BR5: N/A | BS5: N/A | BT5: N/A | BU5: N/A | BV5: N/A | BW5: N/A | BX5: N/A | BY5: TCO SCM Logistics | BZ5: 4559 | CB5: YES | CC5: 40 | CD5: 1.5 | CE5: Emergency | CG5: SCM Logistics: Yerbol Nauryzbay / Yerlan Yeshmagambetov
A6: 108022 | B6: Active | C6: H089106 | D6: TRUCK HD RECOVERY KENWORTH T800 | E6: TMF1 | F6: HDV Heavy Duty Vehicle | G6: Tengiz | H6: 1NKDH08X2ER412644 | I6: 1NKDH08X2ER412644 | J6: 13780 | K6: =IFERROR(VLOOKUP(J6,'CC directory'!A:B,2,),"") -> ACTIVE | L6: =IFERROR(VLOOKUP(J6,'CC directory'!A:D,4,),"") -> 200 | M6: =VLOOKUP(J6,'CC directory'!A:I,9,) -> Heavy Equipment Operations | N6: =IFERROR(VLOOKUP(J6,'CC directory'!A:C,3,),"") -> Operations | O6: =IFERROR(VLOOKUP(J6,'CC directory'!A:F,6,),"") -> 209 | P6: =IFERROR(VLOOKUP(J6,'CC directory'!A:E,5,),"") -> Supply Chain Management | Q6: =IFERROR(VLOOKUP(J6,'CC directory'!A:H,8,),"") -> 322 | R6: =IFERROR(VLOOKUP(J6,'CC directory'!A:G,7,),"") -> Tengiz Ground Transportation | S6: SCM Logistics | T6: Heavy Equipment Operations | U6: 520 | V6: Tengiz fleet | Z6: Non-Critical | AA6: KENWORTH | AB6: T800 | AC6: USD | AD6: 175180 | AE6: 2013 | AF6: 9 | AH6: 35320148 | AJ6: ED00014225 | AK6: 41829 | AL6: 15 | AM6: 41830 | AO6: 207348 | AP6: 207348 | AR6: 11R22.5 | AS6: 11R22.5 | AT6: TRKKEN 007 | AU6: 192678 | AV6: 2024 | AW6: 2029 | AZ6: 521 | BA6: IN-LINE 6 | BD6: =IF((BE6+BG6+BI6)>0, "YES", "NO") -> YES | BE6: 1 | BF6: KENWORTH H 089106 (ТШО 108022) | BG6: 1 | BH6: H 089106 | BI6: 0 | BK6: Industrial Base | BL6: Self-propelled motorized (HDV/HDE) - Wheeled | BM6: =VLOOKUP(BL6,'directory all'!C:D,2,) -> Mileage, engine hours, GPS | BN6: Recovery/service truck | BO6: Shared without conditions | BQ6: 10600 | BR6: N/A | BS6: N/A | BT6: N/A | BU6: N/A | BV6: N/A | BW6: N/A | BX6: N/A | BY6: TCO SCM Logistics | BZ6: 4559 | CB6: YES | CC6: 40 | CD6: 1.5 | CG6: SCM Logistics: Yerbol Nauryzbay / Yerlan Yeshmagambetov
A7: 110008 | B7: Active | C7: 861EAB | D7: TRACTOR WHEELED JCB FASTRAC 2155 | E7: TMF1 | F7: HDV Heavy Duty Vehicle | G7: Tengiz | H7: JCB26H60700742575 | I7: JCB26H60700742575 | J7: 20850 | K7: =IFERROR(VLOOKUP(J7,'CC directory'!A:B,2,),"") -> ACTIVE | L7: =IFERROR(VLOOKUP(J7,'CC directory'!A:D,4,),"") -> 200 | M7: =VLOOKUP(J7,'CC directory'!A:I,9,) -> Maintenance Shared Services | N7: =IFERROR(VLOOKUP(J7,'CC directory'!A:C,3,),"") -> Operations | O7: =IFERROR(VLOOKUP(J7,'CC directory'!A:F,6,),"") -> 207 | P7: =IFERROR(VLOOKUP(J7,'CC directory'!A:E,5,),"") -> Production Operations | Q7: =IFERROR(VLOOKUP(J7,'CC directory'!A:H,8,),"") -> 705 | R7: =IFERROR(VLOOKUP(J7,'CC directory'!A:G,7,),"") -> Maintenance | S7: Maintenance | T7: Maintenance Shared Services | U7: 521 | V7: Tengiz fleet | Z7: Non-Critical | AA7: JCB | AB7: FASTRAC 2155 | AC7: USD | AD7: 118500 | AE7: 2010 | AF7: 13 | AH7: 21946004 | AJ7: 93012 | AK7: 40360 | AL7: 20 | AM7: 40367 | AO7: 25850 | AP7: 25850 | AQ7: 25765.00 mh#1 | AR7: 480/70 R-30 TM- | AS7: 480/70 R30 TM-7 | AT7: CONTW 005 | AU7: 141408 | AV7: 2020 | AW7: 2030 | AY7: YES | AZ7: 522 | BA7: 6 (V) | BD7: =IF((BE7+BG7+BI7)>0, "YES", "NO") -> YES | BE7: 1 | BF7: JCB FASTRAC 861EAB (ТШО 110008) | BG7: 0 | BI7: 0 | BK7: TFM/АРП | BL7: Self-propelled motorized (HDV/HDE) - Wheeled | BM7: =VLOOKUP(BL7,'directory all'!C:D,2,) -> Mileage, engine hours, GPS | BN7: Road construction and cleaning equipment | BO7: Shared with conditions | BQ7: N/A | BR7: N/A | BS7: N/A | BT7: N/A | BU7: N/A | BV7: N/A | BW7: N/A | BX7: N/A | BY7: TCO SCM Logistics | BZ7: 200-4410 | CA7: msslte@tengizchevroil.com | CB7: YES | CC7: 18.279 | CD7: 7.236 | CG7: Maintenance: Assylbek Amangaliyev / Yerkin Dauletov
A8: 110009 | B8: Active | C8: 087EAD | D8: TRACTOR WHEELED KUBOTA M9540DTC | E8: TMF1 | F8: HDV Heavy Duty Vehicle | G8: Tengiz | H8: M9540D87065 | I8: M9540D87065 | J8: 20850 | K8: =IFERROR(VLOOKUP(J8,'CC directory'!A:B,2,),"") -> ACTIVE | L8: =IFERROR(VLOOKUP(J8,'CC directory'!A:D,4,),"") -> 200 | M8: =VLOOKUP(J8,'CC directory'!A:I,9,) -> Maintenance Shared Services | N8: =IFERROR(VLOOKUP(J8,'CC directory'!A:C,3,),"") -> Operations | O8: =IFERROR(VLOOKUP(J8,'CC directory'!A:F,6,),"") -> 207 | P8: =IFERROR(VLOOKUP(J8,'CC directory'!A:E,5,),"") -> Production Operations | Q8: =IFERROR(VLOOKUP(J8,'CC directory'!A:H,8,),"") -> 705 | R8: =IFERROR(VLOOKUP(J8,'CC directory'!A:G,7,),"") -> Maintenance | S8: Maintenance | T8: Maintenance Shared Services | U8: 522 | V8: Tengiz fleet | Z8: Non-Critical | AA8: KUBOTA | AB8: M9540DTC | AC8: USD | AD8: 44993 | AE8: 2011 | AF8: 12 | AH8: AY1569 | AJ8: KGI093656 | AK8: 40807 | AL8: 20 | AM8: 40811 | AO8: 22142 | AP8: 22142 | AQ8: 21957.00 mh#1 | AR8: 12.4/24 | AS8: 18.4/30 | AT8: CONTW006 | AU8: 156681 | AV8: 2021 | AW8: 2031 | AZ8: 523 | BA8: INLINE 4 | BD8: =IF((BE8+BG8+BI8)>0, "YES", "NO") -> NO | BE8: 0 | BG8: 0 | BI8: 0 | BK8: TFM/АРП | BL8: Self-propelled motorized (HDV/HDE) - Wheeled | BM8: =VLOOKUP(BL8,'directory all'!C:D,2,) -> Mileage, engine hours, GPS | BN8: Road construction and cleaning equipment | BO8: Shared with conditions | BQ8: N/A | BR8: N/A | BS8: N/A | BT8: N/A | BU8: N/A | BV8: N/A | BW8: N/A | BX8: N/A | BY8: TCO SCM Logistics | BZ8: 200-4410 | CA8: msslte@tengizchevroil.com | CG8: Maintenance: Assylbek Amangaliyev / Yerkin Dauletov
A9: 110010 | B9: Active | C9: 322EAD | D9: TRACTOR WHEELED JCB HMV 2155 | E9: TMF1 | F9: HDV Heavy Duty Vehicle | G9: Tengiz | H9: JCB26H60V00743037 | I9: JCB26H60V00743037 | J9: 20550 | K9: =IFERROR(VLOOKUP(J9,'CC directory'!A:B,2,),"") -> ACTIVE | L9: =IFERROR(VLOOKUP(J9,'CC directory'!A:D,4,),"") -> 150 | M9: =VLOOKUP(J9,'CC directory'!A:I,9,) -> WM Tengiz - Base | N9: =IFERROR(VLOOKUP(J9,'CC directory'!A:C,3,),"") -> OE/HSE | O9: =IFERROR(VLOOKUP(J9,'CC directory'!A:F,6,),"") -> 205 | P9: =IFERROR(VLOOKUP(J9,'CC directory'!A:E,5,),"") -> OE/HSE | Q9: =IFERROR(VLOOKUP(J9,'CC directory'!A:H,8,),"") -> 607 | R9: =IFERROR(VLOOKUP(J9,'CC directory'!A:G,7,),"") -> Tengiz OE/HSE | S9: Tengiz OE/HSE | T9: WM Tengiz - Base | U9: 523 | V9: Tengiz fleet | Z9: Non-Critical | AA9: JCB | AB9: HMV 2155 | AC9: USD | AD9: 152000 | AE9: 2013 | AF9: 10 | AH9: 22083777 | AJ9: KGI216455 | AK9: 41558 | AL9: 20 | AM9: 41563 | AO9: 3678 | AP9: 3678 | AQ9: 3550.00 mh#1 | AR9: 480/70 R-30 TM- | AS9: 480/70 R30 TM-7 | AT9: CONTW 005 | AU9: 185781 | AV9: 2023 | AW9: 2033 | AZ9: 524 | BA9: IN-LINE 6 | BD9: =IF((BE9+BG9+BI9)>0, "YES", "NO") -> YES | BE9: 1 | BF9: JCB 322 EAD (ТШО 110010) | BG9: 0 | BI9: 0 | BK9: Tengiz Eco Centre | BL9: Self-propelled motorized (HDV/HDE) - Wheeled | BM9: =VLOOKUP(BL9,'directory all'!C:D,2,) -> Mileage, engine hours, GPS | BN9: Road construction and cleaning equipment | BO9: Shared with conditions | BQ9: N/A | BR9: N/A | BS9: N/A | BT9: information missing | BU9: 600–1000 А | BV9: 12 В / 100–120 А | BW9: ~8–10 bar | BX9: ~60–80 m³/h | BY9: TCO SCM Logistics | BZ9: 2234 | CA9: envsvs@tengizchevroil.com | CB9: YES | CD9: 10 | CF9: Currently used in TEC | CG9: Tengiz Base: Azamat Kurmanov / Rustem Konyrbayev
A10: 110011 | B10: Active | C10: AOD112E | D10: TRACTOR WHEELED KUBOTA M5-111 | E10: TMF1 | F10: HDV Heavy Duty Vehicle | G10: Tengiz | H10: KBTMGEDCCG8053456 | I10: KBTMGEDCCG8053456 | J10: 20850 | K10: =IFERROR(VLOOKUP(J10,'CC directory'!A:B,2,),"") -> ACTIVE | L10: =IFERROR(VLOOKUP(J10,'CC directory'!A:D,4,),"") -> 200 | M10: =VLOOKUP(J10,'CC directory'!A:I,9,) -> Maintenance Shared Services | N10: =IFERROR(VLOOKUP(J10,'CC directory'!A:C,3,),"") -> Operations | O10: =IFERROR(VLOOKUP(J10,'CC directory'!A:F,6,),"") -> 207 | P10: =IFERROR(VLOOKUP(J10,'CC directory'!A:E,5,),"") -> Production Operations | Q10: =IFERROR(VLOOKUP(J10,'CC directory'!A:H,8,),"") -> 705 | R10: =IFERROR(VLOOKUP(J10,'CC directory'!A:G,7,),"") -> Maintenance | S10: Maintenance | T10: Maintenance Shared Services | U10: 524 | V10: Tengiz fleet | Z10: Non-Critical | AA10: KUBOTA Corporation | AB10: M5-111 | AC10: GBP | AD10: 46033.15 | AE10: 2017 | AF10: 6 | AH10: 2GU0561 | AI10: 43046 | AJ10: ACY000350 | AL10: 20 | AM10: 43027 | AO10: 22095 | AP10: 22095 | AQ10: 5919.00 mh#1 | AR10: 360/70 R 24 | AS10: 480/70 R 34 | AT10: CONTW 009 | AU10: 267694 | AV10: 2027 | AW10: 2037 | AZ10: 525 | BD10: =IF((BE10+BG10+BI10)>0, "YES", "NO") -> YES | BE10: 1 | BF10: KUBOTA AOD112E (ТШО 110011) | BG10: 0 | BI10: 0 | BK10: TFM/АРП | BL10: Self-propelled motorized (HDV/HDE) - Wheeled | BM10: =VLOOKUP(BL10,'directory all'!C:D,2,) -> Mileage, engine hours, GPS | BN10: Road construction and cleaning equipment | BO10: Shared with conditions | BQ10: N/A | BR10: N/A | BS10: N/A | BT10: N/A | BU10: N/A | BV10: N/A | BW10: N/A | BX10: N/A | BY10: TCO SCM Logistics | BZ10: 200-4410 | CA10: msslte@tengizchevroil.com | CB10: YES | CC10: 18.279 | CD10: 7.236 | CG10: Maintenance: Assylbek Amangaliyev / Yerkin Dauletov
A11: 110012 | B11: Active | C11: 238EAC | D11: TRACTOR WHEELED JCB FASTRAC 4160 | E11: TMF1 | F11: HDV Heavy Duty Vehicle | G11: Tengiz | H11: JCB41Y60CK2765293 | I11: JCB41Y60CK2765293 | J11: 20850 | K11: =IFERROR(VLOOKUP(J11,'CC directory'!A:B,2,),"") -> ACTIVE | L11: =IFERROR(VLOOKUP(J11,'CC directory'!A:D,4,),"") -> 200 | M11: =VLOOKUP(J11,'CC directory'!A:I,9,) -> Maintenance Shared Services | N11: =IFERROR(VLOOKUP(J11,'CC directory'!A:C,3,),"") -> Operations | O11: =IFERROR(VLOOKUP(J11,'CC directory'!A:F,6,),"") -> 207 | P11: =IFERROR(VLOOKUP(J11,'CC directory'!A:E,5,),"") -> Production Operations | Q11: =IFERROR(VLOOKUP(J11,'CC directory'!A:H,8,),"") -> 705 | R11: =IFERROR(VLOOKUP(J11,'CC directory'!A:G,7,),"") -> Maintenance | S11: Maintenance | T11: Maintenance Shared Services | U11: 525 | V11: Tengiz fleet | Z11: Non-Critical | AA11: JCB Construction Equipment | AB11: FASTRAC 4160U | AC11: KZT | AD11: 106080800 | AE11: 2019 | AF11: 4 | AH11: JLKD371202 | AI11: 43713 | AJ11: ACУ000818 | AK11: 43683 | AL11: 20 | AM11: 43692 | AO11: 5562 | AP11: 5562 | AQ11: 4350.00 mh#1 | AR11: 500/70R24 | AS11: 500/70R24 | AT11: CONTW 007 | AU11: 303021 | AV11: 2029 | AW11: 2039 | AZ11: 526 | BD11: =IF((BE11+BG11+BI11)>0, "YES", "NO") -> YES | BE11: 1 | BF11: JCB 238EAC (ТШО 110012) | BG11: 0 | BI11: 0 | BK11: Plant KTL/Завод КТЛ | BL11: Self-propelled motorized (HDV/HDE) - Wheeled | BM11: =VLOOKUP(BL11,'directory all'!C:D,2,) -> Mileage, engine hours, GPS | BN11: Road construction and cleaning equipment | BO11: Shared with conditions | BQ11: N/A | BR11: N/A | BS11: N/A | BT11: N/A | BU11: N/A | BV11: N/A | BW11: N/A | BX11: N/A | BY11: TCO SCM Logistics | BZ11: 200-4410 | CA11: msslte@tengizchevroil.com | CB11: YES | CC11: 18.279 | CD11: 7.236 | CG11: Maintenance: Assylbek Amangaliyev / Yerkin Dauletov
A12: 110013 | B12: Active | C12: E138ACD | D12: TRACTOR WHEELED 6110B | E12: TMF1 | F12: HDV Heavy Duty Vehicle | G12: Tengiz | H12: 1YR6110BEND530287 | I12: 1YR6110BEND530287 | J12: 20850 | K12: =IFERROR(VLOOKUP(J12,'CC directory'!A:B,2,),"") -> ACTIVE | L12: =IFERROR(VLOOKUP(J12,'CC directory'!A:D,4,),"") -> 200 | M12: =VLOOKUP(J12,'CC directory'!A:I,9,) -> Maintenance Shared Services | N12: =IFERROR(VLOOKUP(J12,'CC directory'!A:C,3,),"") -> Operations | O12: =IFERROR(VLOOKUP(J12,'CC directory'!A:F,6,),"") -> 207 | P12: =IFERROR(VLOOKUP(J12,'CC directory'!A:E,5,),"") -> Production Operations | Q12: =IFERROR(VLOOKUP(J12,'CC directory'!A:H,8,),"") -> 705 | R12: =IFERROR(VLOOKUP(J12,'CC directory'!A:G,7,),"") -> Maintenance | S12: Maintenance | T12: Maintenance Shared Services | U12: 526 | V12: Tengiz fleet | Z12: Non-Critical | AA12: JOHN DEERE | AB12: 6110B | AC12: KZT | AD12: 35497050 | AE12: 2022 | AF12: 1 | AH12: PE4045N033113 | AI12: 44868 | AJ12: АТБ000568 | AK12: 44942 | AL12: 10 | AM12: 44852 | AO12: 6 | AP12: 6 | AQ12: 50.00 mh#1 | AR12: 380/85R24 | AS12: 420/85R38 | AT12: CONTW 008 | AU12: 371202 | AV12: 2032 | AW12: 2032 | AZ12: 527 | BD12: =IF((BE12+BG12+BI12)>0, "YES", "NO") -> YES | BE12: 1 | BF12: JohnDeere E138 ACD TCO110013 | BG12: 0 | BI12: 0 | BK12: Plant KTL/Завод КТЛ | BL12: Self-propelled motorized (HDV/HDE) - Wheeled | BM12: =VLOOKUP(BL12,'directory all'!C:D,2,) -> Mileage, engine hours, GPS | BN12: Road construction and cleaning equipment | BO12: Shared with conditions | BQ12: N/A | BR12: N/A | BS12: N/A | BT12: N/A | BU12: N/A | BV12: N/A | BW12: N/A | BX12: N/A | BY12: TCO SCM Logistics | BZ12: 200-4410 | CA12: msslte@tengizchevroil.com | CB12: YES | CC12: 18.279 | CD12: 7.236 | CG12: Maintenance: Assylbek Amangaliyev / Yerkin Dauletov
A13: 110014 | B13: Active | C13: E140ACD | D13: TRACTOR WHEELED 6110B | E13: TMF1 | F13: HDV Heavy Duty Vehicle | G13: Tengiz | H13: 1YR6110BKND530294 | I13: 1YR6110BKND530294 | J13: 20850 | K13: =IFERROR(VLOOKUP(J13,'CC directory'!A:B,2,),"") -> ACTIVE | L13: =IFERROR(VLOOKUP(J13,'CC directory'!A:D,4,),"") -> 200 | M13: =VLOOKUP(J13,'CC directory'!A:I,9,) -> Maintenance Shared Services | N13: =IFERROR(VLOOKUP(J13,'CC directory'!A:C,3,),"") -> Operations | O13: =IFERROR(VLOOKUP(J13,'CC directory'!A:F,6,),"") -> 207 | P13: =IFERROR(VLOOKUP(J13,'CC directory'!A:E,5,),"") -> Production Operations | Q13: =IFERROR(VLOOKUP(J13,'CC directory'!A:H,8,),"") -> 705 | R13: =IFERROR(VLOOKUP(J13,'CC directory'!A:G,7,),"") -> Maintenance | S13: Maintenance | T13: Maintenance Shared Services | U13: 527 | V13: Tengiz fleet | Z13: Non-Critical | AA13: JOHN DEERE | AB13: 6110B | AC13: KZT | AD13: 35497050 | AE13: 2022 | AF13: 1 | AH13: PE4045N034602 | AI13: 44868 | AJ13: АТБ000570 | AK13: 44955 | AL13: 10 | AM13: 44852 | AO13: 5 | AP13: 5 | AQ13: 51.00 mh#1 | AR13: 380/85R24 | AS13: 420/85R38 | AT13: CONTW 008 | AU13: 371202 | AV13: 2032 | AW13: 2032 | AZ13: 528 | BD13: =IF((BE13+BG13+BI13)>0, "YES", "NO") -> YES | BE13: 1 | BF13: John Deere E140 ACD TCO110014 | BG13: 0 | BI13: 0 | BK13: Plant KTL/Завод КТЛ | BL13: Self-propelled motorized (HDV/HDE) - Wheeled | BM13: =VLOOKUP(BL13,'directory all'!C:D,2,) -> Mileage, engine hours, GPS | BN13: Road construction and cleaning equipment | BO13: Shared with conditions | BQ13: N/A | BR13: N/A | BS13: N/A | BT13: N/A | BU13: N/A | BV13: N/A | BW13: N/A | BX13: N/A | BY13: TCO SCM Logistics | BZ13: 200-4410 | CA13: msslte@tengizchevroil.com | CB13: YES | CC13: 18.279 | CD13: 7.236 | CG13: Maintenance: Assylbek Amangaliyev / Yerkin Dauletov
A14: 110015 | B14: Active | C14: E139ACD | D14: TRACTOR WHEELED 6110B | E14: TMF1 | F14: HDV Heavy Duty Vehicle | G14: Tengiz | H14: 1YR6110BCND530296 | I14: 1YR6110BCND530296 | J14: 20850 | K14: =IFERROR(VLOOKUP(J14,'CC directory'!A:B,2,),"") -> ACTIVE | L14: =IFERROR(VLOOKUP(J14,'CC directory'!A:D,4,),"") -> 200 | M14: =VLOOKUP(J14,'CC directory'!A:I,9,) -> Maintenance Shared Services | N14: =IFERROR(VLOOKUP(J14,'CC directory'!A:C,3,),"") -> Operations | O14: =IFERROR(VLOOKUP(J14,'CC directory'!A:F,6,),"") -> 207 | P14: =IFERROR(VLOOKUP(J14,'CC directory'!A:E,5,),"") -> Production Operations | Q14: =IFERROR(VLOOKUP(J14,'CC directory'!A:H,8,),"") -> 705 | R14: =IFERROR(VLOOKUP(J14,'CC directory'!A:G,7,),"") -> Maintenance | S14: Maintenance | T14: Maintenance Shared Services | U14: 528 | V14: Tengiz fleet | Z14: Non-Critical | AA14: JOHN DEERE | AB14: 6110B | AC14: KZT | AD14: 35497050 | AE14: 2022 | AF14: 1 | AH14: PE4045N034398 | AI14: 44868 | AJ14: АТБ000569 | AK14: 44967 | AL14: 10 | AM14: 44852 | AO14: 5 | AP14: 5 | AQ14: 78.00 mh#1 | AR14: 380/85R24 | AS14: 420/85R38 | AT14: CONTW 008 | AU14: 371202 | AV14: 2032 | AW14: 2032 | AZ14: 529 | BD14: =IF((BE14+BG14+BI14)>0, "YES", "NO") -> YES | BE14: 1 | BF14: John Deere E139 ACD TCO 110015 | BG14: 0 | BI14: 0 | BK14: Plant KTL/Завод КТЛ | BL14: Self-propelled motorized (HDV/HDE) - Wheeled | BM14: =VLOOKUP(BL14,'directory all'!C:D,2,) -> Mileage, engine hours, GPS | BN14: Road construction and cleaning equipment | BO14: Shared with conditions | BQ14: N/A | BR14: N/A | BS14: N/A | BT14: N/A | BU14: N/A | BV14: N/A | BW14: N/A | BX14: N/A | BY14: TCO SCM Logistics | BZ14: 200-4410 | CA14: msslte@tengizchevroil.com | CB14: YES | CC14: 18.279 | CD14: 7.236 | CG14: Maintenance: Assylbek Amangaliyev / Yerkin Dauletov
A15: 111012 | B15: Active | C15: H032206 | D15: TRUCK HD CHEMICAL 3000 GAL KENWORTH T370 | E15: TMF1 | F15: HDV Heavy Duty Vehicle | G15: Tengiz | H15: 2NKHLZ9X8DM354323 | I15: 2NKHLZ9X8DM354323 | J15: 13780 | K15: =IFERROR(VLOOKUP(J15,'CC directory'!A:B,2,),"") -> ACTIVE | L15: =IFERROR(VLOOKUP(J15,'CC directory'!A:D,4,),"") -> 200 | M15: =VLOOKUP(J15,'CC directory'!A:I,9,) -> Heavy Equipment Operations | N15: =IFERROR(VLOOKUP(J15,'CC directory'!A:C,3,),"") -> Operations | O15: =IFERROR(VLOOKUP(J15,'CC directory'!A:F,6,),"") -> 209 | P15: =IFERROR(VLOOKUP(J15,'CC directory'!A:E,5,),"") -> Supply Chain Management | Q15: =IFERROR(VLOOKUP(J15,'CC directory'!A:H,8,),"") -> 322 | R15: =IFERROR(VLOOKUP(J15,'CC directory'!A:G,7,),"") -> Tengiz Ground Transportation | S15: SCM Logistics | T15: Heavy Equipment Operations | U15: 529 | V15: Tengiz fleet | Z15: Critical | AA15: KENWORTH | AB15: T370 | AC15: USD | AD15: 172300 | AE15: 2012 | AF15: 10 | AH15: 73399913 | AJ15: ED00013282 | AK15: 41314 | AL15: 15 | AM15: 41331 | AO15: 137132 | AP15: 137132 | AR15: 11R22.5 | AS15: 11R22.5 | AT15: TRKKEN 006 | AU15: 168690 | AV15: 2023 | AW15: 2028 | AY15: YES | AZ15: 530 | BA15: IN-LINE 6 | BB15: FSO6406A | BD15: =IF((BE15+BG15+BI15)>0, "YES", "NO") -> YES | BE15: 1 | BF15: KENWORTH H 0322 06 (ТШО 111012) | BG15: 1 | BH15: H 032206 | BI15: 0 | BK15: Industrial Base | BL15: Self-propelled motorized (HDV/HDE) - Wheeled | BM15: =VLOOKUP(BL15,'directory all'!C:D,2,) -> Mileage, engine hours, GPS | BN15: Chemical truck | BO15: Shared without conditions | BQ15: N/A | BR15: 10 | BS15: N/A | BT15: N/A | BU15: N/A | BV15: N/A | BW15: N/A | BX15: N/A | BY15: TCO SCM Logistics | BZ15: 3148 | CB15: YES | CC15: 40 | CD15: 1.5 | CG15: SCM Logistics: Yerbol Nauryzbay / Yerlan Yeshmagambetov
A16: 111013 | B16: Active | C16: H032106 | D16: TRUCK HD CHEMICAL 3000 GAL KENWORTH T370 | E16: TMF1 | F16: HDV Heavy Duty Vehicle | G16: Tengiz | H16: 2NKHLZ9XXDM354324 | I16: 2NKHLZ9XXDM354324 | J16: 13780 | K16: =IFERROR(VLOOKUP(J16,'CC directory'!A:B,2,),"") -> ACTIVE | L16: =IFERROR(VLOOKUP(J16,'CC directory'!A:D,4,),"") -> 200 | M16: =VLOOKUP(J16,'CC directory'!A:I,9,) -> Heavy Equipment Operations | N16: =IFERROR(VLOOKUP(J16,'CC directory'!A:C,3,),"") -> Operations | O16: =IFERROR(VLOOKUP(J16,'CC directory'!A:F,6,),"") -> 209 | P16: =IFERROR(VLOOKUP(J16,'CC directory'!A:E,5,),"") -> Supply Chain Management | Q16: =IFERROR(VLOOKUP(J16,'CC directory'!A:H,8,),"") -> 322 | R16: =IFERROR(VLOOKUP(J16,'CC directory'!A:G,7,),"") -> Tengiz Ground Transportation | S16: SCM Logistics | T16: Heavy Equipment Operations | U16: 530 | V16: Tengiz fleet | Z16: Critical | AA16: KENWORTH | AB16: T370 | AC16: USD | AD16: 172300 | AE16: 2012 | AF16: 10 | AH16: 73399914 | AJ16: ED00013281 | AK16: 41314 | AL16: 15 | AM16: 41331 | AO16: 139094 | AP16: 139094 | AR16: 11R22.5 | AS16: 11R22.5 | AT16: TRKKEN 006 | AU16: 168690 | AV16: 2023 | AW16: 2028 | AY16: YES | AZ16: 531 | BA16: IN-LINE 6 | BB16: FSO6406A | BD16: =IF((BE16+BG16+BI16)>0, "YES", "NO") -> YES | BE16: 1 | BF16: KENWORTH H 032106 (ТШО 111013) | BG16: 1 | BH16: H 032106 | BI16: 0 | BK16: Industrial Base | BL16: Self-propelled motorized (HDV/HDE) - Wheeled | BM16: =VLOOKUP(BL16,'directory all'!C:D,2,) -> Mileage, engine hours, GPS | BN16: Chemical truck | BO16: Shared without conditions | BQ16: N/A | BR16: 10 | BS16: N/A | BT16: N/A | BU16: N/A | BV16: N/A | BW16: N/A | BX16: N/A | BY16: TCO SCM Logistics | BZ16: 3336 / 7068 | CB16: YES | CC16: 40 | CD16: 1.5 | CG16: SCM Logistics: Yerbol Nauryzbay / Yerlan Yeshmagambetov
A17: 111015 | B17: Reserved | C17: H531506 | D17: TRUCK HD CHEMICAL 20 TONN HINO 67443C | E17: TMF1 | F17: HDV Heavy Duty Vehicle | G17: TENGIZ | H17: JHDFS1EUU00010086 | I17: MX967443CP0021173 | J17: 20850 | K17: =IFERROR(VLOOKUP(J17,'CC directory'!A:B,2,),"") -> ACTIVE | L17: =IFERROR(VLOOKUP(J17,'CC directory'!A:D,4,),"") -> 200 | M17: =VLOOKUP(J17,'CC directory'!A:I,9,) -> Maintenance Shared Services | N17: =IFERROR(VLOOKUP(J17,'CC directory'!A:C,3,),"") -> Operations | O17: =IFERROR(VLOOKUP(J17,'CC directory'!A:F,6,),"") -> 207 | P17: =IFERROR(VLOOKUP(J17,'CC directory'!A:E,5,),"") -> Production Operations | Q17: =IFERROR(VLOOKUP(J17,'CC directory'!A:H,8,),"") -> 705 | R17: =IFERROR(VLOOKUP(J17,'CC directory'!A:G,7,),"") -> Maintenance | S17: Maintenance | T17: Maintenance Shared Services | U17: 2183 | V17: Tengiz Fleet | Y17: 45237 | Z17: Critical | AA17: HINO | AB17: 67443C | AC17: KZT | AD17: 1.4817747e+08 | AE17: 2023 | AI17: 45268 | AJ17: EW00013960 | AK17: 45237 | AL17: 10 | AM17: 45237 | AP17: 30 | AU17: 376020 | AV17: 2033 | AW17: 2033 | AZ17: 2390 | BB17: HINO, NX07 | BC17: 06.01.2024-sutz: The status was changed to "Reserved", according to the e-mail from Registration Department with confirmed by TCO Transportation Team Lead as of 16.12.2023. (Inbox-Registration Department as of 18.12.2023) It is direct order from the customer. Assigned to CC 20850 - Maintenance Shared Services. (Inbox-Registration Dept as of 11.11.2023) | BD17: =IF((BE17+BG17+BI17)>0, "YES", "NO") -> YES | BE17: 1 | BF17: HINO H531506 ТШО 111015 | BG17: 1 | BH17: H 531506 | BI17: 0 | BK17: TFM/АРП | BL17: Self-propelled motorized (HDV/HDE) - Wheeled | BM17: =VLOOKUP(BL17,'directory all'!C:D,2,) -> Mileage, engine hours, GPS | BN17: Chemical truck | BO17: Shared with conditions | BQ17: 20000 | BR17: N/A | BS17: N/A | BT17: N/A | BU17: N/A | BV17: N/A | BW17: N/A | BX17: N/A | BY17: TCO SCM Logistics | BZ17: 200-4401 | CA17: mssls@tengizchevroil.com | CB17: YES | CC17: 18.279 | CD17: 1.257 | CG17: Maintenance: Assylbek Amangaliyev / Yerkin Dauletov
A18: 115015 | B18: Active | C18: H724244 | D18: TRUCK HD LUBE KENWORTH T800 | E18: TMF1 | F18: HDV Heavy Duty Vehicle | G18: Tengiz | H18: 1NKDL40X3AJ272775 | I18: 1NKDL40X3AJ272775 | J18: 13780 | K18: =IFERROR(VLOOKUP(J18,'CC directory'!A:B,2,),"") -> ACTIVE | L18: =IFERROR(VLOOKUP(J18,'CC directory'!A:D,4,),"") -> 200 | M18: =VLOOKUP(J18,'CC directory'!A:I,9,) -> Heavy Equipment Operations | N18: =IFERROR(VLOOKUP(J18,'CC directory'!A:C,3,),"") -> Operations | O18: =IFERROR(VLOOKUP(J18,'CC directory'!A:F,6,),"") -> 209 | P18: =IFERROR(VLOOKUP(J18,'CC directory'!A:E,5,),"") -> Supply Chain Management | Q18: =IFERROR(VLOOKUP(J18,'CC directory'!A:H,8,),"") -> 322 | R18: =IFERROR(VLOOKUP(J18,'CC directory'!A:G,7,),"") -> Tengiz Ground Transportation | S18: SCM Logistics | T18: Heavy Equipment Operations | U18: 585 | V18: Tengiz fleet | Z18: Non-Critical | AA18: KENWORTH | AB18: T800 | AC18: USD | AD18: 279445 | AE18: 2009 | AF18: 13 | AH18: 79395703 | AJ18: ED00010973 | AK18: 40231 | AL18: 15 | AM18: 40255 | AO18: 241165 | AP18: 241165 | AR18: 425/65R22.5 | AS18: 11R24 | AT18: TRKKEN 002 | AU18: 135773 | AV18: 2022 | AW18: 2025 | AY18: YES | AZ18: 586 | BD18: =IF((BE18+BG18+BI18)>0, "YES", "NO") -> YES | BE18: 1 | BF18: KENWORTH H 724244 (ТШО 115015) | BG18: 1 | BH18: H 724244 | BI18: 0 | BK18: Industrial Base | BL18: Self-propelled motorized (HDV/HDE) - Wheeled | BM18: =VLOOKUP(BL18,'directory all'!C:D,2,) -> Mileage, engine hours, GPS | BN18: Recovery/service truck | BO18: Shared without conditions | BQ18: 8850 | BR18: N/A | BS18: N/A | BT18: N/A | BU18: N/A | BV18: N/A | BW18: N/A | BX18: N/A | BY18: TCO SCM Logistics | BZ18: 7514 | CB18: YES | CC18: 30 | CG18: SCM Logistics: Yerbol Nauryzbay / Yerlan Yeshmagambetov
A19: 116014 | B19: Active | C19: 229EAD | D19: TRACTOR AIRCRAFT TOW (TUG) AWD | E19: TMF1 | F19: HDV Heavy Duty Vehicle | G19: Tengiz | H19: 6182 | I19: 6182 | J19: 13727 | K19: =IFERROR(VLOOKUP(J19,'CC directory'!A:B,2,),"") -> ACTIVE | L19: =IFERROR(VLOOKUP(J19,'CC directory'!A:D,4,),"") -> 200 | M19: =VLOOKUP(J19,'CC directory'!A:I,9,) -> Flight Ops & Charters | N19: =IFERROR(VLOOKUP(J19,'CC directory'!A:C,3,),"") -> Operations | O19: =IFERROR(VLOOKUP(J19,'CC directory'!A:F,6,),"") -> 209 | P19: =IFERROR(VLOOKUP(J19,'CC directory'!A:E,5,),"") -> Supply Chain Management | Q19: =IFERROR(VLOOKUP(J19,'CC directory'!A:H,8,),"") -> 321 | R19: =IFERROR(VLOOKUP(J19,'CC directory'!A:G,7,),"") -> Aviation & Logistics | S19: SCM Logistics | T19: AVIATION OPERATIONS | U19: 587 | V19: Tengiz fleet | Z19: Critical | AA19: EAGLE | AB19: TT-6D | AC19: USD | AD19: 55575 | AE19: 2012 | AF19: 10 | AH19: L6822 | AJ19: KGI095084 | AK19: 41331 | AL19: 15 | AM19: 41335 | AO19: 1314 | AP19: 1314 | AQ19: 1234.00 mh#1 | AR19: R8.75-16.5 | AS19: R8.75-16.5 | AT19: TUG 001 | AU19: 172729 | AV19: 2023 | AW19: 2028 | AZ19: 588 | BA19: INLINE 4 | BD19: =IF((BE19+BG19+BI19)>0, "YES", "NO") -> NO | BE19: 0 | BG19: 0 | BI19: 0 | BK19: Aerodrome | BL19: Self-propelled motorized (HDV/HDE) - Wheeled | BM19: =VLOOKUP(BL19,'directory all'!C:D,2,) -> Mileage, engine hours, GPS | BN19: HD truck (tractor) | BO19: Assigned | BP19: Aerdrodrome purpose | BQ19: 3765 | BS19: 12 | BT19: 100 - 120 Ah | BU19: 80 A | BW19: Hydraulic | BY19: TCO SCM Logistics | BZ19: 3370 | CA19: opstng@tengizchevroil.com | CG19: SCM Aviation: Nurzat Khairolla / Zhandos Ospankulov
A20: 117018 | B20: Sent to BP | C20: H176506 | D20: TRUCK HD TRACTOR HYUNDAI HD-1000 | E20: N-COCR | F20: HDV Heavy Duty Vehicle | G20: Tengiz | H20: KMEFG18SPAC046237 | I20: KMEFG18SPAC046237 | J20: 20850 | K20: =IFERROR(VLOOKUP(J20,'CC directory'!A:B,2,),"") -> ACTIVE | L20: =IFERROR(VLOOKUP(J20,'CC directory'!A:D,4,),"") -> 200 | M20: =VLOOKUP(J20,'CC directory'!A:I,9,) -> Maintenance Shared Services | N20: =IFERROR(VLOOKUP(J20,'CC directory'!A:C,3,),"") -> Operations | O20: =IFERROR(VLOOKUP(J20,'CC directory'!A:F,6,),"") -> 207 | P20: =IFERROR(VLOOKUP(J20,'CC directory'!A:E,5,),"") -> Production Operations | Q20: =IFERROR(VLOOKUP(J20,'CC directory'!A:H,8,),"") -> 705 | R20: =IFERROR(VLOOKUP(J20,'CC directory'!A:G,7,),"") -> Maintenance | S20: Maintenance | T20: Maintenance Shared Services | U20: 1462 | V20: Tengiz Fleet | Z20: Critical | AA20: HYUNDAI | AB20: HD-1000 | AC20: USD | AD20: 96619 | AE20: 2010 | AF20: 13 | AI20: 1 | AJ20: ED00015573 | AK20: 40277 | AL20: 15 | AM20: 40491 | AO20: 22725 | AP20: 22725 | AR20: 12R22,5 | AS20: 12R22,5 | AT20: TRKHUI 002 | AU20: 142062 | AV20: 2022 | AW20: 2025 | AY20: YES | AZ20: 1668 | BA20: 6 | BB20: ZF165151 | BC20: 06.10.23-sutz: CC was changed from 13780 - Heavy Equipment Operations to 20850 - Maintenance Shared Services, according to the e-mail from TCO Transportation Team Lead’s Erbol with confirmed as of 03.10.2023 (Inbox - CC Change). COCR will no longer provide maintenance, and the OTTO department will now carry out repairs, therefore not registered in E-MAINT and Fleet Management Tool systems. | BD20: =IF((BE20+BG20+BI20)>0, "YES", "NO") -> YES | BE20: 1 | BF20: HYUNDAI H176506 (ТШО 117018) | BG20: 1 | BH20: H 176506 | BI20: 0 | BK20: Plant KTL/Завод КТЛ | BL20: Self-propelled motorized (HDV/HDE) - Wheeled | BM20: =VLOOKUP(BL20,'directory all'!C:D,2,) -> Mileage, engine hours, GPS | BN20: HD truck (tractor) | BO20: Shared with conditions | BQ20: N/A | BR20: N/A | BS20: N/A | BT20: N/A | BU20: N/A | BV20: N/A | BW20: N/A | BX20: N/A | BY20: TCO MSS BP | BZ20: 200-4401 | CA20: mssls@tengizchevroil.com | CB20: YES | CC20: 18.279 | CD20: 2.359 | CG20: Maintenance: Assylbek Amangaliyev / Yerkin Dauletov
A21: 117019 | B21: Active | C21: H725109 | D21: TRUCK HD TRACTOR HYUNDAI HD-1000 | E21: TMF1 | F21: HDV Heavy Duty Vehicle | G21: Tengiz | H21: KMEFG18SPAC046236 | I21: KMEFG18SPAC046236 | J21: 13780 | K21: =IFERROR(VLOOKUP(J21,'CC directory'!A:B,2,),"") -> ACTIVE | L21: =IFERROR(VLOOKUP(J21,'CC directory'!A:D,4,),"") -> 200 | M21: =VLOOKUP(J21,'CC directory'!A:I,9,) -> Heavy Equipment Operations | N21: =IFERROR(VLOOKUP(J21,'CC directory'!A:C,3,),"") -> Operations | O21: =IFERROR(VLOOKUP(J21,'CC directory'!A:F,6,),"") -> 209 | P21: =IFERROR(VLOOKUP(J21,'CC directory'!A:E,5,),"") -> Supply Chain Management | Q21: =IFERROR(VLOOKUP(J21,'CC directory'!A:H,8,),"") -> 322 | R21: =IFERROR(VLOOKUP(J21,'CC directory'!A:G,7,),"") -> Tengiz Ground Transportation | S21: SCM Logistics | T21: Heavy Equipment Operations | U21: 588 | V21: Tengiz fleet | Z21: Critical | AA21: HYUNDAI | AB21: HD-1000 | AC21: USD | AD21: 96619 | AE21: 2010 | AF21: 13 | AJ21: ED00011313 | AK21: 40425 | AL21: 15 | AM21: 40432 | AO21: 281702 | AP21: 200426 | AR21: 12R22,5 | AS21: 12R22,5 | AT21: TRKHUI 002 | AU21: 142062 | AV21: 2022 | AW21: 2025 | AY21: YES | AZ21: 590 | BA21: 6 | BB21: ZF165151 | BD21: =IF((BE21+BG21+BI21)>0, "YES", "NO") -> YES | BE21: 1 | BF21: HYUNDAI H725109 (ТШО 117019) | BG21: 1 | BH21: H 725109 | BI21: 0 | BK21: Industrial Base | BL21: Self-propelled motorized (HDV/HDE) - Wheeled | BM21: =VLOOKUP(BL21,'directory all'!C:D,2,) -> Mileage, engine hours, GPS | BN21: HD truck (tractor) | BO21: Shared without conditions | BQ21: N/A | BR21: N/A | BS21: N/A | BT21: N/A | BU21: N/A | BV21: N/A | BW21: N/A | BX21: N/A | BY21: TCO SCM Logistics | BZ21: 5158 | CB21: YES | CC21: 40 | CE21: In preservation | CF21: Long downtime time, decision for write off is pending | CG21: SCM Logistics: Yerbol Nauryzbay / Yerlan Yeshmagambetov
A22: 117020 | B22: Active | C22: H494106 | D22: TRUCK HD MAN TGS-41.400 | E22: TMF1 | F22: HDV Heavy Duty Vehicle | G22: Tengiz | H22: WMA39WZZ3CP033399 | I22: WMA39WZZ3CP033399 | J22: 20850 | K22: =IFERROR(VLOOKUP(J22,'CC directory'!A:B,2,),"") -> ACTIVE | L22: =IFERROR(VLOOKUP(J22,'CC directory'!A:D,4,),"") -> 200 | M22: =VLOOKUP(J22,'CC directory'!A:I,9,) -> Maintenance Shared Services | N22: =IFERROR(VLOOKUP(J22,'CC directory'!A:C,3,),"") -> Operations | O22: =IFERROR(VLOOKUP(J22,'CC directory'!A:F,6,),"") -> 207 | P22: =IFERROR(VLOOKUP(J22,'CC directory'!A:E,5,),"") -> Production Operations | Q22: =IFERROR(VLOOKUP(J22,'CC directory'!A:H,8,),"") -> 705 | R22: =IFERROR(VLOOKUP(J22,'CC directory'!A:G,7,),"") -> Maintenance | S22: Maintenance | T22: Maintenance Shared Services | U22: 589 | V22: Tengiz fleet | Z22: Non-Critical | AA22: MAN | AB22: TGS-41.400 | AC22: GBP | AD22: 104330.7 | AE22: 2011 | AF22: 11 | AH22: 5.05301E+13 | AI22: 45565 | AJ22: ED99999853 | AK22: 40986 | AL22: 15 | AM22: 40995 | AO22: 99353 | AP22: 99353 | AR22: 315/80R22.5 | AS22: 315/80R22.5 | AT22: TRKHUI 003 | AU22: 158544 | AV22: 2024 | AW22: 2027 | AZ22: 591 | BB22: ZF16 S | BC22: 01.10.2024 xeza: License plate and technical passport was changed according to the e-mail from Registration Dept as of 01.10.24. (Inbox-Registration Dept). 12.02.24-sutz: CC was changed to 20850 - Maintenance Shared Services, according to the e-mail from Registration Dept with confirmed by Fleet maintenance and inspection Team Lead as of 07.02.2024 (Inbox - CC Change) | BD22: =IF((BE22+BG22+BI22)>0, "YES", "NO") -> YES | BE22: 1 | BF22: МАN Н725768 (ТШО 117020) | BG22: 1 | BH22: H 494106 | BI22: 0 | BK22: Plant KTL/Завод КТЛ | BL22: Self-propelled motorized (HDV/HDE) - Wheeled | BM22: =VLOOKUP(BL22,'directory all'!C:D,2,) -> Mileage, engine hours, GPS | BN22: HD truck (tractor) | BO22: Shared with conditions | BQ22: N/A | BR22: N/A | BS22: N/A | BT22: N/A | BU22: N/A | BV22: N/A | BW22: N/A | BX22: N/A | BY22: TCO SCM Logistics | BZ22: 200-4401 | CA22: mssls@tengizchevroil.com | CB22: YES | CC22: 189.9744 | CG22: Maintenance: Assylbek Amangaliyev / Yerkin Dauletov
A23: 117021 | B23: Active | C23: H497706 | D23: TRUCK HD MAN TGS-41.400 | E23: TMF1 | F23: HDV Heavy Duty Vehicle | G23: Tengiz | H23: WMA39WZZ8CP033897 | I23: WMA39WZZ8CP033897 | J23: 20850 | K23: =IFERROR(VLOOKUP(J23,'CC directory'!A:B,2,),"") -> ACTIVE | L23: =IFERROR(VLOOKUP(J23,'CC directory'!A:D,4,),"") -> 200 | M23: =VLOOKUP(J23,'CC directory'!A:I,9,) -> Maintenance Shared Services | N23: =IFERROR(VLOOKUP(J23,'CC directory'!A:C,3,),"") -> Operations | O23: =IFERROR(VLOOKUP(J23,'CC directory'!A:F,6,),"") -> 207 | P23: =IFERROR(VLOOKUP(J23,'CC directory'!A:E,5,),"") -> Production Operations | Q23: =IFERROR(VLOOKUP(J23,'CC directory'!A:H,8,),"") -> 705 | R23: =IFERROR(VLOOKUP(J23,'CC directory'!A:G,7,),"") -> Maintenance | S23: Maintenance | T23: Maintenance Shared Services | U23: 590 | V23: Tengiz fleet | Z23: Non-Critical | AA23: MAN | AB23: TGS-41.400 | AC23: GBP | AD23: 104330.7 | AE23: 2011 | AF23: 11 | AH23: 5.05303E+13 | AI23: 45593 | AJ23: ED99999829 | AK23: 40986 | AL23: 15 | AM23: 40995 | AO23: 64042 | AP23: 64042 | AR23: 315/80R22.5 | AS23: 315/80R22.5 | AT23: TRKHUI 003 | AU23: 158544 | AV23: 2024 | AW23: 2027 | AZ23: 592 | BB23: ZF16 S | BC23: 29.10.24-sutz: Because the old license plate H725767 of the vehicle was damaged and invalid, a new license plate & technical passport was received, according to the e-mail from Registration department as of 29.10.24. (Inbox-Registration Dept) 16.02.24-sutz: CC was changed to 20850 - Maintenance Shared Services, according to the e-mail from Registration Dept with confirmed by Fleet maintenance and inspection Team Lead as of 07.02.2024 (Inbox - CC Change) | BD23: =IF((BE23+BG23+BI23)>0, "YES", "NO") -> YES | BE23: 1 | BF23: МАN Н497706 (ТШО 117021) | BG23: 1 | BH23: H 497706 | BI23: 0 | BK23: Plant KTL/Завод КТЛ | BL23: Self-propelled motorized (HDV/HDE) - Wheeled | BM23: =VLOOKUP(BL23,'directory all'!C:D,2,) -> Mileage, engine hours, GPS | BN23: HD truck (tractor) | BO23: Shared with conditions | BQ23: N/A | BR23: N/A | BS23: N/A | BT23: N/A | BU23: N/A | BV23: N/A | BW23: N/A | BX23: N/A | BY23: TCO SCM Logistics | BZ23: 200-4401 | CA23: mssls@tengizchevroil.com | CB23: YES | CC23: 42.294 | CD23: 2.359 | CG23: Maintenance: Assylbek Amangaliyev / Yerkin Dauletov
A24: 117022 | B24: Active | C24: H209306 | D24: TRUCK HD FRAC TANK TRACTOR W/WINCH KENWO | E24: TMF1 | F24: HDV Heavy Duty Vehicle | G24: Tengiz | H24: 1XDD40X2FR467214 | I24: 1XDD40X2FR467214 | J24: 20850 | K24: =IFERROR(VLOOKUP(J24,'CC directory'!A:B,2,),"") -> ACTIVE | L24: =IFERROR(VLOOKUP(J24,'CC directory'!A:D,4,),"") -> 200 | M24: =VLOOKUP(J24,'CC directory'!A:I,9,) -> Maintenance Shared Services | N24: =IFERROR(VLOOKUP(J24,'CC directory'!A:C,3,),"") -> Operations | O24: =IFERROR(VLOOKUP(J24,'CC directory'!A:F,6,),"") -> 207 | P24: =IFERROR(VLOOKUP(J24,'CC directory'!A:E,5,),"") -> Production Operations | Q24: =IFERROR(VLOOKUP(J24,'CC directory'!A:H,8,),"") -> 705 | R24: =IFERROR(VLOOKUP(J24,'CC directory'!A:G,7,),"") -> Maintenance | S24: Maintenance | T24: Maintenance Shared Services | U24: 591 | V24: Tengiz fleet | Z24: Non-Critical | AA24: KENWORTH | AB24: T800 | AC24: USD | AD24: 204296 | AE24: 2014 | AF24: 8 | AH24: 79789562 | AI24: 42948 | AJ24: ED00016106 | AL24: 15 | AM24: 42185 | AO24: 51489 | AP24: 51489 | AR24: 315/80R22.5 | AS24: 315/80R22.5 | AT24: TRKKEN 007 | AU24: 215308 | AV24: 2027 | AW24: 2030 | AY24: YES | AZ24: 593 | BC24: 14.02.24-sutz: CC was changed to 20850 - Maintenance Shared Services, according to the e-mail from Registration Dept with confirmed by Fleet maintenance and inspection Team Lead as of 07.02.2024 (Inbox - CC Change) | BD24: =IF((BE24+BG24+BI24)>0, "YES", "NO") -> YES | BE24: 1 | BF24: KENWORTH Н209306 (ТШО 117022) | BG24: 1 | BH24: H 209306 | BI24: 0 | BK24: Plant KTL/Завод КТЛ | BL24: Self-propelled motorized (HDV/HDE) - Wheeled | BM24: =VLOOKUP(BL24,'directory all'!C:D,2,) -> Mileage, engine hours, GPS | BN24: HD truck (tractor) | BO24: Shared with conditions | BQ24: 52000 | BR24: N/A | BS24: N/A | BT24: N/A | BU24: N/A | BV24: N/A | BW24: N/A | BX24: N/A | BY24: TCO SCM Logistics | BZ24: 200-4410 | CA24: msslte@tengizchevroil.com | CB24: YES | CC24: 18.279 | CD24: 4.668 | CG24: Maintenance: Assylbek Amangaliyev / Yerkin Dauletov
A25: 117023 | B25: Active | C25: H176206 | D25: TRUCK KAMAZ-65201 MULTILIFT HOOK LOADER | E25: TMF1 | F25: HDV Heavy Duty Vehicle | G25: Tengiz | H25: Z9L780425G0000001 | I25: XTC652014G1333206 | J25: 20850 | K25: =IFERROR(VLOOKUP(J25,'CC directory'!A:B,2,),"") -> ACTIVE | L25: =IFERROR(VLOOKUP(J25,'CC directory'!A:D,4,),"") -> 200 | M25: =VLOOKUP(J25,'CC directory'!A:I,9,) -> Maintenance Shared Services | N25: =IFERROR(VLOOKUP(J25,'CC directory'!A:C,3,),"") -> Operations | O25: =IFERROR(VLOOKUP(J25,'CC directory'!A:F,6,),"") -> 207 | P25: =IFERROR(VLOOKUP(J25,'CC directory'!A:E,5,),"") -> Production Operations | Q25: =IFERROR(VLOOKUP(J25,'CC directory'!A:H,8,),"") -> 705 | R25: =IFERROR(VLOOKUP(J25,'CC directory'!A:G,7,),"") -> Maintenance | S25: Maintenance | T25: Maintenance Shared Services | U25: 592 | V25: Tengiz fleet | Z25: Non-Critical | AA25: KAMAZ-65201 | AB25: 780425 | AC25: KZT | AD25: 40421931 | AE25: 2016 | AF25: 7 | AG25: 2416532 | AI25: 42606 | AJ25: ED00015556 | AL25: 15 | AM25: 42567 | AO25: 9601 | AP25: 9601 | AR25: 315/80R22.5 | AS25: 315/80R22.5 | AT25: TRKHUI | AU25: 249668 | AV25: 2026 | AW25: 2031 | AY25: YES | AZ25: 594 | BC25: 16.02.24-sutz: CC was changed to 20850 - Maintenance Shared Services, according to the e-mail from Registration Dept with confirmed by Fleet maintenance and inspection Team Lead as of 07.02.2024 (Inbox - CC Change) | BD25: =IF((BE25+BG25+BI25)>0, "YES", "NO") -> YES | BE25: 1 | BF25: KAMAZ H176206 (ТШО 117023) | BG25: 1 | BH25: H 176206 | BI25: 0 | BK25: TFM/АРП | BL25: Self-propelled motorized (HDV/HDE) - Wheeled | BM25: =VLOOKUP(BL25,'directory all'!C:D,2,) -> Mileage, engine hours, GPS | BN25: Dump truck | BO25: Shared with conditions | BQ25: 25500 | BR25: N/A | BS25: N/A | BT25: N/A | BU25: N/A | BV25: N/A | BW25: N/A | BX25: N/A | BY25: TCO SCM Logistics | BZ25: 200-4401 | CA25: mssls@tengizchevroil.com | CB25: YES | CC25: 18.279 | CD25: 2.359 | CE25: Seasonal (SGP TA) | CG25: Maintenance: Assylbek Amangaliyev / Yerkin Dauletov
A26: 117024 | B26: Active | C26: H190606 | D26: TRUCK KAMAZ-65201 MULTILIFT HOOK LOADER | E26: TMF1 | F26: HDV Heavy Duty Vehicle | G26: Tengiz | H26: XTC652014G1343353 | I26: XTC652014G1343353 | J26: 20850 | K26: =IFERROR(VLOOKUP(J26,'CC directory'!A:B,2,),"") -> ACTIVE | L26: =IFERROR(VLOOKUP(J26,'CC directory'!A:D,4,),"") -> 200 | M26: =VLOOKUP(J26,'CC directory'!A:I,9,) -> Maintenance Shared Services | N26: =IFERROR(VLOOKUP(J26,'CC directory'!A:C,3,),"") -> Operations | O26: =IFERROR(VLOOKUP(J26,'CC directory'!A:F,6,),"") -> 207 | P26: =IFERROR(VLOOKUP(J26,'CC directory'!A:E,5,),"") -> Production Operations | Q26: =IFERROR(VLOOKUP(J26,'CC directory'!A:H,8,),"") -> 705 | R26: =IFERROR(VLOOKUP(J26,'CC directory'!A:G,7,),"") -> Maintenance | S26: Maintenance | T26: Maintenance Shared Services | U26: 593 | V26: Tengiz fleet | Z26: Non-Critical | AA26: KAMAZ | AB26: 65201 | AC26: KZT | AD26: 45070872 | AE26: 2016 | AF26: 6 | AG26: 2436044 | AH26: 78572250 | AI26: 42798 | AJ26: ED00015855 | AL26: 15 | AM26: 42720 | AO26: 11448 | AP26: 11448 | AR26: 315/80R22,5 | AS26: 315/80R22,5 | AT26: TRKHUI001 | AU26: 252800 | AV26: 2026 | AW26: 2031 | AY26: YES | AZ26: 595 | BC26: 16.02.24-sutz: CC was changed to 20850 - Maintenance Shared Services, according to the e-mail from Registration Dept with confirmed by Fleet maintenance and inspection Team Lead as of 07.02.2024 (Inbox - CC Change) | BD26: =IF((BE26+BG26+BI26)>0, "YES", "NO") -> YES | BE26: 1 | BF26: КАМАЗ H190606 (ТШО 117024) | BG26: 1 | BH26: H 190606 | BI26: 0 | BK26: TFM/АРП | BL26: Self-propelled motorized (HDV/HDE) - Wheeled | BM26: =VLOOKUP(BL26,'directory all'!C:D,2,) -> Mileage, engine hours, GPS | BN26: Dump truck | BO26: Shared with conditions | BQ26: 25500 | BR26: N/A | BS26: N/A | BT26: N/A | BU26: N/A | BV26: N/A | BW26: N/A | BX26: N/A | BY26: TCO SCM Logistics | BZ26: 200-4401 | CA26: mssls@tengizchevroil.com | CB26: YES | CC26: 18.279 | CD26: 2.359 | CE26: Seasonal (SGP TA) | CG26: Maintenance: Assylbek Amangaliyev / Yerkin Dauletov
A27: 117025 | B27: Sent to BP | C27: H192506 | D27: TRUCK HD HOOK LOADER KENWORTH T800 | E27: N-COCR | F27: HDV Heavy Duty Vehicle | G27: Tengiz | H27: 1NKDX4TX1HR166014 | I27: 1NKDX4TX1HR166014 | J27: 9601120346 | K27: =IFERROR(VLOOKUP(J27,'CC directory'!A:B,2,),"") -> ACTIVE | L27: =IFERROR(VLOOKUP(J27,'CC directory'!A:D,4,),"") -> 200 | M27: =VLOOKUP(J27,'CC directory'!A:I,9,) -> SpecAccum-Drilling Support Srv | N27: =IFERROR(VLOOKUP(J27,'CC directory'!A:C,3,),"") -> Operations | O27: =IFERROR(VLOOKUP(J27,'CC directory'!A:F,6,),"") -> 203 | P27: =IFERROR(VLOOKUP(J27,'CC directory'!A:E,5,),"") -> Drilling | Q27: =IFERROR(VLOOKUP(J27,'CC directory'!A:H,8,),"") -> 500 | R27: =IFERROR(VLOOKUP(J27,'CC directory'!A:G,7,),"") -> Drilling | S27: Drilling | T27: SpecAccum-Drilling Support Srv | U27: 1463 | V27: Tengiz Fleet | Z27: Non-Critical | AA27: Kenworth | AB27: T800 | AC27: KZT | AD27: 79593919 | AE27: 2016 | AF27: 6 | AH27: 79939873 | AI27: 43105 | AJ27: ED00015957 | AK27: 43051 | AL27: 15 | AM27: 43225 | AO27: 50 | AP27: 50 | AR27: 315/80 R22.5 | AS27: 315/80 R22.5 | AT27: TRKHUI002 | AU27: 253584 | AV27: 2027 | AW27: 2032 | AY27: NO | AZ27: 1669 | BD27: =IF((BE27+BG27+BI27)>0, "YES", "NO") -> YES | BE27: 0 | BG27: 1 | BH27: H 192506 | BI27: 0 | BK27: Unassigned | BL27: Self-propelled motorized (HDV/HDE) - Wheeled | BM27: =VLOOKUP(BL27,'directory all'!C:D,2,) -> Mileage, engine hours, GPS | BN27: Hook loader truck | BO27: Shared with conditions | BP27: Wells primary use | BQ27: 33309 | BR27: 14 | BS27: N/A | BT27: N/A | BU27: N/A | BV27: N/A | BW27: N/A | BX27: N/A | BY27: AGI | BZ27: 933-4124 | CA27: jr-ops-mgr@arctic-group.com | CB27: YES | CD27: 12 | CG27: Drilling: Kyle Harrelson / Joseph Bothner
A28: 117026 | B28: Sent to BP | C28: H205106 | D28: TRUCK HD HOOK LOADER KENWORTH T800 | E28: N-COCR | F28: HDV Heavy Duty Vehicle | G28: Tengiz | H28: 1NKDX4TX3HR166015 | I28: 1NKDX4TX3HR166015 | J28: 9601120346 | K28: =IFERROR(VLOOKUP(J28,'CC directory'!A:B,2,),"") -> ACTIVE | L28: =IFERROR(VLOOKUP(J28,'CC directory'!A:D,4,),"") -> 200 | M28: =VLOOKUP(J28,'CC directory'!A:I,9,) -> SpecAccum-Drilling Support Srv | N28: =IFERROR(VLOOKUP(J28,'CC directory'!A:C,3,),"") -> Operations | O28: =IFERROR(VLOOKUP(J28,'CC directory'!A:F,6,),"") -> 203 | P28: =IFERROR(VLOOKUP(J28,'CC directory'!A:E,5,),"") -> Drilling | Q28: =IFERROR(VLOOKUP(J28,'CC directory'!A:H,8,),"") -> 500 | R28: =IFERROR(VLOOKUP(J28,'CC directory'!A:G,7,),"") -> Drilling | S28: Drilling | T28: SpecAccum-Drilling Support Srv | U28: 1464 | V28: Tengiz Fleet | Z28: Non-Critical | AA28: Kenworth | AB28: T800 | AC28: KZT | AD28: 79593919 | AE28: 2016 | AF28: 6 | AH28: 79939874 | AI28: 43105 | AJ28: ED00015958 | AK28: 43051 | AL28: 15 | AM28: 43225 | AO28: 0 | AP28: 0 | AR28: 315/80 R22.5 | AS28: 315/80 R22.5 | AT28: TRKHUI002 | AU28: 253584 | AV28: 2027 | AW28: 2032 | AY28: NO | AZ28: 1670 | BD28: =IF((BE28+BG28+BI28)>0, "YES", "NO") -> YES | BE28: 0 | BG28: 1 | BH28: H 205106 | BI28: 0 | BK28: Unassigned | BL28: Self-propelled motorized (HDV/HDE) - Wheeled | BM28: =VLOOKUP(BL28,'directory all'!C:D,2,) -> Mileage, engine hours, GPS | BN28: Hook loader truck | BO28: Shared with conditions | BP28: Wells primary use | BQ28: 33309 | BR28: 14 | BS28: N/A | BT28: N/A | BU28: N/A | BV28: N/A | BW28: N/A | BX28: N/A | BY28: AGI | BZ28: 933-4124 | CA28: jr-ops-mgr@arctic-group.com | CB28: YES | CD28: 12 | CG28: Drilling: Kyle Harrelson / Joseph Bothner
A29: 117027 | B29: Sent to BP | C29: H205206 | D29: TRUCK HD HOOK LOADER KENWORTH T800 | E29: N-COCR | F29: HDV Heavy Duty Vehicle | G29: Tengiz | H29: 1NKDX4TX5HR166016 | I29: 1NKDX4TX5HR166016 | J29: 9601120346 | K29: =IFERROR(VLOOKUP(J29,'CC directory'!A:B,2,),"") -> ACTIVE | L29: =IFERROR(VLOOKUP(J29,'CC directory'!A:D,4,),"") -> 200 | M29: =VLOOKUP(J29,'CC directory'!A:I,9,) -> SpecAccum-Drilling Support Srv | N29: =IFERROR(VLOOKUP(J29,'CC directory'!A:C,3,),"") -> Operations | O29: =IFERROR(VLOOKUP(J29,'CC directory'!A:F,6,),"") -> 203 | P29: =IFERROR(VLOOKUP(J29,'CC directory'!A:E,5,),"") -> Drilling | Q29: =IFERROR(VLOOKUP(J29,'CC directory'!A:H,8,),"") -> 500 | R29: =IFERROR(VLOOKUP(J29,'CC directory'!A:G,7,),"") -> Drilling | S29: Drilling | T29: SpecAccum-Drilling Support Srv | U29: 1465 | V29: Tengiz Fleet | Z29: Non-Critical | AA29: Kenworth | AB29: T800 | AC29: KZT | AD29: 79593919 | AE29: 2016 | AF29: 6 | AH29: 79939382 | AI29: 43105 | AJ29: ED00015959 | AK29: 43051 | AL29: 15 | AM29: 43225 | AO29: 0 | AP29: 0 | AR29: 315/80 R22.5 | AS29: 315/80 R22.5 | AT29: TRKHUI002 | AU29: 253584 | AV29: 2027 | AW29: 2032 | AY29: NO | AZ29: 1671 | BD29: =IF((BE29+BG29+BI29)>0, "YES", "NO") -> YES | BE29: 0 | BG29: 1 | BH29: H 205206 | BI29: 0 | BK29: Unassigned | BL29: Self-propelled motorized (HDV/HDE) - Wheeled | BM29: =VLOOKUP(BL29,'directory all'!C:D,2,) -> Mileage, engine hours, GPS | BN29: Hook loader truck | BO29: Shared with conditions | BP29: Wells primary use | BQ29: 33309 | BR29: N/A | BS29: N/A | BT29: N/A | BU29: N/A | BV29: N/A | BW29: N/A | BX29: N/A | BY29: AGI | BZ29: 933-4124 | CA29: jr-ops-mgr@arctic-group.com | CB29: YES | CD29: 12 | CG29: Drilling: Kyle Harrelson / Joseph Bothner
A30: 117028 | B30: Sent to BP | C30: H205506 | D30: TRUCK HD HOOK LOADER KENWORTH T800 | E30: N-COCR | F30: HDV Heavy Duty Vehicle | G30: Tengiz | H30: 1NKDX4TX7HR166017 | I30: 1NKDX4TX7HR166017 | J30: 9601120346 | K30: =IFERROR(VLOOKUP(J30,'CC directory'!A:B,2,),"") -> ACTIVE | L30: =IFERROR(VLOOKUP(J30,'CC directory'!A:D,4,),"") -> 200 | M30: =VLOOKUP(J30,'CC directory'!A:I,9,) -> SpecAccum-Drilling Support Srv | N30: =IFERROR(VLOOKUP(J30,'CC directory'!A:C,3,),"") -> Operations | O30: =IFERROR(VLOOKUP(J30,'CC directory'!A:F,6,),"") -> 203 | P30: =IFERROR(VLOOKUP(J30,'CC directory'!A:E,5,),"") -> Drilling | Q30: =IFERROR(VLOOKUP(J30,'CC directory'!A:H,8,),"") -> 500 | R30: =IFERROR(VLOOKUP(J30,'CC directory'!A:G,7,),"") -> Drilling | S30: Drilling | T30: SpecAccum-Drilling Support Srv | U30: 1466 | V30: Tengiz Fleet | Z30: Non-Critical | AA30: Kenworth | AB30: T800 | AC30: KZT | AD30: 79593919 | AE30: 2016 | AF30: 6 | AH30: 79939381 | AI30: 43105 | AJ30: ED00015962 | AK30: 43051 | AL30: 15 | AM30: 43225 | AO30: 0 | AP30: 0 | AR30: 315/80 R22.5 | AS30: 315/80 R22.5 | AT30: TRKHUI002 | AU30: 253584 | AV30: 2027 | AW30: 2032 | AY30: NO | AZ30: 1672 | BD30: =IF((BE30+BG30+BI30)>0, "YES", "NO") -> YES | BE30: 0 | BG30: 1 | BH30: H 205506 | BI30: 0 | BK30: Unassigned | BL30: Self-propelled motorized (HDV/HDE) - Wheeled | BM30: =VLOOKUP(BL30,'directory all'!C:D,2,) -> Mileage, engine hours, GPS | BN30: Hook loader truck | BO30: Shared with conditions | BP30: Wells primary use | BQ30: 30000 | BR30: 15 | BS30: N/A | BT30: N/A | BU30: N/A | BV30: N/A | BW30: N/A | BX30: N/A | BY30: AGI | BZ30: 933-4124 | CA30: jr-ops-mgr@arctic-group.com | CB30: YES | CD30: 12 | CG30: Drilling: Kyle Harrelson / Joseph Bothner
A31: 117029 | B31: Sent to BP | C31: H205406 | D31: TRUCK HD HOOK LOADER KENWORTH T800 | E31: N-COCR | F31: HDV Heavy Duty Vehicle | G31: Tengiz | H31: 1NKDX4TX9HR166018 | I31: 1NKDX4TX9HR166018 | J31: 9601120346 | K31: =IFERROR(VLOOKUP(J31,'CC directory'!A:B,2,),"") -> ACTIVE | L31: =IFERROR(VLOOKUP(J31,'CC directory'!A:D,4,),"") -> 200 | M31: =VLOOKUP(J31,'CC directory'!A:I,9,) -> SpecAccum-Drilling Support Srv | N31: =IFERROR(VLOOKUP(J31,'CC directory'!A:C,3,),"") -> Operations | O31: =IFERROR(VLOOKUP(J31,'CC directory'!A:F,6,),"") -> 203 | P31: =IFERROR(VLOOKUP(J31,'CC directory'!A:E,5,),"") -> Drilling | Q31: =IFERROR(VLOOKUP(J31,'CC directory'!A:H,8,),"") -> 500 | R31: =IFERROR(VLOOKUP(J31,'CC directory'!A:G,7,),"") -> Drilling | S31: Drilling | T31: SpecAccum-Drilling Support Srv | U31: 1467 | V31: Tengiz Fleet | Z31: Non-Critical | AA31: Kenworth | AB31: T800 | AC31: KZT | AD31: 79593919 | AE31: 2016 | AF31: 6 | AH31: 79940351 | AI31: 43105 | AJ31: ED00015961 | AK31: 43051 | AL31: 15 | AM31: 43225 | AO31: 0 | AP31: 0 | AR31: 315/80 R22.5 | AS31: 315/80 R22.5 | AT31: TRKHUI002 | AU31: 253584 | AV31: 2027 | AW31: 2032 | AY31: NO | AZ31: 1673 | BD31: =IF((BE31+BG31+BI31)>0, "YES", "NO") -> YES | BE31: 0 | BG31: 1 | BH31: H 205406 | BI31: 0 | BK31: Unassigned | BL31: Self-propelled motorized (HDV/HDE) - Wheeled | BM31: =VLOOKUP(BL31,'directory all'!C:D,2,) -> Mileage, engine hours, GPS | BN31: Hook loader truck | BO31: Shared with conditions | BP31: Wells primary use | BQ31: 33309 | BR31: 14 | BS31: N/A | BT31: N/A | BU31: N/A | BV31: N/A | BW31: N/A | BX31: N/A | BY31: AGI | BZ31: 933-4124 | CA31: jr-ops-mgr@arctic-group.com | CB31: YES | CD31: 12 | CG31: Drilling: Kyle Harrelson / Joseph Bothner
A32: 117030 | B32: Sent to BP | C32: H205306 | D32: TRUCK HD HOOK LOADER KENWORTH T800 | E32: N-COCR | F32: HDV Heavy Duty Vehicle | G32: Tengiz | H32: 1NKDX4TX0HR166019 | I32: 1NKDX4TX0HR166019 | J32: 9601120346 | K32: =IFERROR(VLOOKUP(J32,'CC directory'!A:B,2,),"") -> ACTIVE | L32: =IFERROR(VLOOKUP(J32,'CC directory'!A:D,4,),"") -> 200 | M32: =VLOOKUP(J32,'CC directory'!A:I,9,) -> SpecAccum-Drilling Support Srv | N32: =IFERROR(VLOOKUP(J32,'CC directory'!A:C,3,),"") -> Operations | O32: =IFERROR(VLOOKUP(J32,'CC directory'!A:F,6,),"") -> 203 | P32: =IFERROR(VLOOKUP(J32,'CC directory'!A:E,5,),"") -> Drilling | Q32: =IFERROR(VLOOKUP(J32,'CC directory'!A:H,8,),"") -> 500 | R32: =IFERROR(VLOOKUP(J32,'CC directory'!A:G,7,),"") -> Drilling | S32: Drilling | T32: SpecAccum-Drilling Support Srv | U32: 1468 | V32: Tengiz Fleet | Z32: Non-Critical | AA32: Kenworth | AB32: T800 | AC32: KZT | AD32: 79593919 | AE32: 2016 | AF32: 6 | AH32: 79940350 | AI32: 43105 | AJ32: ED00015960 | AK32: 43051 | AL32: 15 | AM32: 43225 | AO32: 0 | AP32: 0 | AR32: 315/80 R22.5 | AS32: 315/80 R22.5 | AT32: TRKHUI002 | AU32: 253584 | AV32: 2027 | AW32: 2032 | AY32: NO | AZ32: 1674 | BD32: =IF((BE32+BG32+BI32)>0, "YES", "NO") -> YES | BE32: 0 | BG32: 1 | BH32: H 205306 | BI32: 0 | BK32: Unassigned | BL32: Self-propelled motorized (HDV/HDE) - Wheeled | BM32: =VLOOKUP(BL32,'directory all'!C:D,2,) -> Mileage, engine hours, GPS | BN32: Hook loader truck | BO32: Shared with conditions | BP32: Wells primary use | BQ32: 30000 | BR32: 15 | BS32: N/A | BT32: N/A | BU32: N/A | BV32: N/A | BW32: N/A | BX32: N/A | BY32: AGI | BZ32: 933-4124 | CA32: jr-ops-mgr@arctic-group.com | CB32: YES | CD32: 12 | CG32: Drilling: Kyle Harrelson / Joseph Bothner
A33: 117032 | B33: Active | C33: H550506 | D33: TRUCK HD MAN TGX 18.400 | E33: TMF1 | F33: HDV Heavy Duty Vehicle | G33: Tengiz | H33: WMA06KZZ2RM941681 | I33: WMA06KZZ2RM941681 | J33: 20850 | K33: =IFERROR(VLOOKUP(J33,'CC directory'!A:B,2,),"") -> ACTIVE | L33: =IFERROR(VLOOKUP(J33,'CC directory'!A:D,4,),"") -> 200 | M33: =VLOOKUP(J33,'CC directory'!A:I,9,) -> Maintenance Shared Services | N33: =IFERROR(VLOOKUP(J33,'CC directory'!A:C,3,),"") -> Operations | O33: =IFERROR(VLOOKUP(J33,'CC directory'!A:F,6,),"") -> 207 | P33: =IFERROR(VLOOKUP(J33,'CC directory'!A:E,5,),"") -> Production Operations | Q33: =IFERROR(VLOOKUP(J33,'CC directory'!A:H,8,),"") -> 705 | R33: =IFERROR(VLOOKUP(J33,'CC directory'!A:G,7,),"") -> Maintenance | S33: Maintenance | T33: Maintenance Shared Services | U33: 2199 | V33: Tengiz Fleet | Y33: 45356 | Z33: Critical | AA33: MAN | AB33: TGX 18.400 4x2 BL SA | AC33: KZT | AD33: 78585000 | AE33: 2023 | AH33: 50568330706834 | AI33: 45416 | AJ33: EW00014812 | AK33: 45356 | AL33: 10 | AM33: 45356 | AT33: TRKHUI004 | AU33: 0060071487-001 | AV33: 2034 | AZ33: 2409 | BC33: 16.05.24-pmlt: Issued from Registration Dept. to 20850 - MSS according to the acceptance act as of 15.05.24 and the e-mail from Registration Department as of 16.05.24. (Inbox - CC Change) | BD33: =IF((BE33+BG33+BI33)>0, "YES", "NO") -> YES | BE33: 1 | BF33: MAN H550506 (ТШО 117032) | BG33: 1 | BH33: H 550506 | BI33: 0 | BK33: TFM/АРП | BL33: Self-propelled motorized (HDV/HDE) - Wheeled | BM33: =VLOOKUP(BL33,'directory all'!C:D,2,) -> Mileage, engine hours, GPS | BN33: HD truck (tractor) | BO33: Shared with conditions | BQ33: N/A | BR33: N/A | BS33: N/A | BT33: N/A | BU33: N/A | BV33: N/A | BW33: N/A | BX33: N/A | BY33: TCO SCM Logistics | BZ33: 200-4401 | CA33: mssls@tengizchevroil.com | CB33: YES | CC33: 18.279 | CD33: 2.359 | CG33: Maintenance: Assylbek Amangaliyev / Yerkin Dauletov
